<?xml version="1.0" encoding="UTF-8"?>
<!-- Generated by org.testng.reporters.JUnitReportReporter -->
<testsuite hostname="Girish-Kalyan-Mac.local" failures="1" tests="3" name="Automated.Tests.NegativeTest" time="67.958" errors="0" timestamp="2025-02-15T16:00:26 IST" skipped="1">
  <testcase classname="Automated.Tests.NegativeTest" name="errorTest" time="17.591">
    <failure message="expected:&lt;Incorrect emailor password.&gt; but was:&lt;Incorrect email or password.&gt;" type="java.lang.AssertionError">
      <![CDATA[java.lang.AssertionError: expected:<Incorrect emailor password.> but was:<Incorrect email or password.>
at org.testng.AssertJUnit.assertEquals(AssertJUnit.java:115)
at org.testng.AssertJUnit.assertEquals(AssertJUnit.java:125)
at Automated.Tests.NegativeTest.errorTest(NegativeTest.java:30)
at java.base/jdk.internal.reflect.DirectMethodHandleAccessor.invoke(DirectMethodHandleAccessor.java:103)
at java.base/java.lang.reflect.Method.invoke(Method.java:580)
at org.testng.internal.MethodInvocationHelper.invokeMethod(MethodInvocationHelper.java:133)
at org.testng.internal.TestInvoker.invokeMethod(TestInvoker.java:598)
at org.testng.internal.TestInvoker.retryFailed(TestInvoker.java:213)
at org.testng.internal.MethodRunner.runInSequence(MethodRunner.java:58)
at org.testng.internal.TestInvoker$MethodInvocationAgent.invoke(TestInvoker.java:824)
at org.testng.internal.TestInvoker.invokeTestMethods(TestInvoker.java:146)
at org.testng.internal.TestMethodWorker.invokeTestMethods(TestMethodWorker.java:146)
at org.testng.internal.TestMethodWorker.run(TestMethodWorker.java:128)
at java.base/java.util.ArrayList.forEach(ArrayList.java:1596)
at org.testng.TestRunner.privateRun(TestRunner.java:794)
at org.testng.TestRunner.run(TestRunner.java:596)
at org.testng.SuiteRunner.runTest(SuiteRunner.java:377)
at org.testng.SuiteRunner.access$000(SuiteRunner.java:28)
at org.testng.SuiteRunner$SuiteWorker.run(SuiteRunner.java:418)
at org.testng.internal.thread.ThreadUtil.lambda$execute$0(ThreadUtil.java:64)
at java.base/java.util.concurrent.FutureTask.run(FutureTask.java:317)
at java.base/java.util.concurrent.ThreadPoolExecutor.runWorker(ThreadPoolExecutor.java:1144)
at java.base/java.util.concurrent.ThreadPoolExecutor$Worker.run(ThreadPoolExecutor.java:642)
at java.base/java.lang.Thread.run(Thread.java:1583)
]]>
    </failure>
  </testcase> <!-- errorTest -->
  <system-out/>
  <testcase classname="Automated.Tests.NegativeTest" name="productErrorValidation" time="34.383"/>
  <system-out/>
  <testcase classname="Automated.Tests.NegativeTest" name="errorTest" time="15.984">
    <skipped/>
  </testcase> <!-- errorTest -->
  <system-out/>
</testsuite> <!-- Automated.Tests.NegativeTest -->
